<mujoco model="dex_robot_simple">
    <compiler angle="degree" coordinate="local" inertiafromgeom="true"/>
    <option integrator="RK4" timestep="0.01"/>
    
    <worldbody>
        <light diffuse=".5 .5 .5" pos="0 0 3" dir="0 0 -1"/>
        <geom name="floor" pos="0 0 0" size="0 0 .25" type="plane" rgba="0.8 0.9 0.8 1"/>
        
        <body name="base" pos="0 0 0.1">
            <geom name="base_geom" type="cylinder" size="0.05 0.1" rgba="0.5 0.5 0.5 1"/>
            <body name="arm_link1" pos="0 0 0.1">
                <joint name="joint1" type="hinge" axis="0 1 0" range="-90 90"/>
                <geom name="link1_geom" type="capsule" size="0.03" fromto="0 0 0 0 0 0.3" rgba="0.7 0.7 0.7 1"/>
                <body name="arm_link2" pos="0 0 0.3">
                    <joint name="joint2" type="hinge" axis="0 1 0" range="-90 90"/>
                    <geom name="link2_geom" type="capsule" size="0.03" fromto="0 0 0 0 0 0.3" rgba="0.7 0.7 0.7 1"/>
                    <body name="hand" pos="0 0 0.3">
                        <site name="hand_site" pos="0 0 0" size="0.01"/>
                        <geom name="hand_geom" type="sphere" size="0.04" rgba="0.1 0.1 0.8 1"/>
                    </body>
                </body>
            </body>
        </body>
    </worldbody>

    <actuator>
        <motor name="motor1" joint="joint1" gear="100"/>
        <motor name="motor2" joint="joint2" gear="100"/>
    </actuator>
</mujoco>
